Workbook

Sheet Grupy Przewodników
A1: Grupa | B1: Przewodnik grupy | C1: Zastępca grupy | D1: Podopieczny | E1: Wymagane akcje | F1: Potrzebni nowi wolontariusze | G1: Wolontariusze | H1: Wymagane akcje | I1: Bieżące informacje
A2: A | B2: Imie i Nazwisko80 | C2: Imie i Nazwisko53 | D2: Podopieczny Nazwisko1 | E2: potrzebne odwiedziny księdza | F2: TAK | G2: Imie i Nazwisko126 | I2: wyjechał do rodzinnego domu
A3: A | D3: Podopieczny Nazwisko2 | F3: NIE | G3: Imie i Nazwisko92 | I3: wyjechał do rodzinnego domu
A4: A | D4: Podopieczny Nazwisko3 | F4: NIE | G4: Imie i Nazwisko54, Imie i Nazwisko43 | I4: wyjechał do rodzinnego domu
A5: A | D5: Podopieczny Nazwisko4 | F5: NIE | G5: Imie i Nazwisko134, Imie i Nazwisko96 | I5: wyjechał do rodzinnego domu
A6: A | D6: Podopieczny Nazwisko5 | F6: NIE | G6: Imie i Nazwisko21, Imie i Nazwisko47 | I6: wyjechał do rodzinnego domu
A7: A | D7: Podopieczny Nazwisko6 | F7: NIE | G7: Imie i Nazwisko77, Imie i Nazwisko127 | I7: wyjechał do rodzinnego domu
A8: B | B8: Imie i Nazwisko52 | C8: Imie i Nazwisko123 | D8: Podopieczny Nazwisko7 | F8: NIE | G8: Imie i Nazwisko49 | I8: wyjechał do rodzinnego domu
A9: B | D9: Podopieczny Nazwisko8 | E9: potrzebne odwiedziny księdza | F9: TAK | G9: Imie i Nazwisko119 | I9: wyjechał do rodzinnego domu
A10: B | D10: Podopieczny Nazwisko9 | F10: TAK | G10: Imie i Nazwisko125, Imie i Nazwisko128 | H10: zakupy | I10: wyjechał do rodzinnego domu
A11: B | D11: Podopieczny Nazwisko10 | F11: NIE | G11: Imie i Nazwisko2, Imie i Nazwisko91 | H11: zakupy | I11: wyjechał do rodzinnego domu
A12: B | D12: Podopieczny Nazwisko11 | F12: TAK | G12: Imie i Nazwisko122, Imie i Nazwisko37 | H12: zakupy | I12: wyjechał do rodzinnego domu
A13: B | D13: Podopieczny Nazwisko12 | F13: TAK | G13: Imie i Nazwisko86, Imie i Nazwisko10 | H13: zakupy | I13: wyjechał do rodzinnego domu
A14: C | B14: Imie i Nazwisko62 | C14: Imie i Nazwisko70 | D14: Podopieczny Nazwisko13 | F14: TAK | G14: Imie i Nazwisko66 | H14: zakupy | I14: wyjechał do rodzinnego domu
A15: C | D15: Podopieczny Nazwisko14 | F15: TAK | G15: Imie i Nazwisko110 | H15: zakupy
A16: C | D16: Podopieczny Nazwisko15 | F16: NIE | G16: Imie i Nazwisko111, Imie i Nazwisko31 | H16: zakupy
A17: C | D17: Podopieczny Nazwisko16 | F17: TAK | G17: Imie i Nazwisko63, Imie i Nazwisko75 | H17: zakupy
A18: D | B18: Imie i Nazwisko29 | C18: Imie i Nazwisko90 | D18: Podopieczny Nazwisko17 | F18: TAK | G18: Imie i Nazwisko135 | H18: zakupy
A19: D | D19: Podopieczny Nazwisko18 | F19: TAK | G19: Imie i Nazwisko56
A20: D | D20: Podopieczny Nazwisko19 | E20: potrzebne odwiedziny księdza | F20: NIE | G20: Imie i Nazwisko129, Imie i Nazwisko4
A21: D | D21: Podopieczny Nazwisko20 | F21: TAK | G21: Imie i Nazwisko24, Imie i Nazwisko48 | H21: teatr
A22: D | D22: Podopieczny Nazwisko21 | F22: TAK | G22: Imie i Nazwisko83, Imie i Nazwisko78 | H22: teatr
A23: D | D23: Podopieczny Nazwisko22 | F23: TAK | G23: Imie i Nazwisko5, Imie i Nazwisko59 | H23: teatr
A24: D | D24: Podopieczny Nazwisko23 | F24: NIE | G24: Imie i Nazwisko102, Imie i Nazwisko79, Imie i Nazwisko94 | H24: teatr
A25: D | D25: Podopieczny Nazwisko24 | F25: TAK | G25: Imie i Nazwisko132, Imie i Nazwisko68, Imie i Nazwisko112 | H25: teatr
A26: E | B26: Imie i Nazwisko133 | C26: Imie i Nazwisko26 | D26: Podopieczny Nazwisko25 | F26: TAK | G26: Imie i Nazwisko20
A27: E | D27: Podopieczny Nazwisko26 | F27: NIE | G27: Imie i Nazwisko76
A28: E | D28: Podopieczny Nazwisko27 | F28: TAK | G28: Imie i Nazwisko115, Imie i Nazwisko130, Imie i Nazwisko74
A29: E | D29: Podopieczny Nazwisko28 | F29: TAK | G29: Imie i Nazwisko45, Imie i Nazwisko73, Imie i Nazwisko44
A30: E | D30: Podopieczny Nazwisko29 | F30: TAK | G30: Imie i Nazwisko99, Imie i Nazwisko36, Imie i Nazwisko57 | H30: rehabilitacje poza krakowem
A31: E | D31: Podopieczny Nazwisko30 | F31: NIE | G31: Imie i Nazwisko15, Imie i Nazwisko85
A32: E | D32: Podopieczny Nazwisko31 | F32: TAK | G32: Imie i Nazwisko71, Imie i Nazwisko64
A33: E | D33: Podopieczny Nazwisko32 | F33: TAK | G33: Imie i Nazwisko13, Imie i Nazwisko32
A34: E | D34: Podopieczny Nazwisko33 | E34: potrzebne odwiedziny księdza | F34: TAK | G34: Imie i Nazwisko30, Imie i Nazwisko28
A35: E | D35: Podopieczny Nazwisko34 | F35: NIE | G35: Imie i Nazwisko109, Imie i Nazwisko11
A36: E | D36: Podopieczny Nazwisko35 | F36: TAK | G36: Imie i Nazwisko124, Imie i Nazwisko41
A37: E | D37: Podopieczny Nazwisko36 | F37: TAK | G37: Imie i Nazwisko116, Imie i Nazwisko14
A38: E | D38: Podopieczny Nazwisko37 | F38: TAK | G38: Imie i Nazwisko106, Imie i Nazwisko1, Imie i Nazwisko19
A39: E | D39: Podopieczny Nazwisko38 | F39: NIE | G39: Imie i Nazwisko72, Imie i Nazwisko22, Imie i Nazwisko67
A40: E | D40: Podopieczny Nazwisko39 | F40: TAK | G40: Imie i Nazwisko84, Imie i Nazwisko117
...

Sheet Rekrutacja Podopiecznych
A1: Nr. | B1: Imię i nazwisko | C1: Adres | D1: Numer telefonu podopiecznego | E1: Osoba zgłaszająca | F1: Imię i nazwisko | G1: Numer telefonu | H1: Opis | I1: BO | J1: Status | K1: Wymagane akcje | L1: Potrzebne odwiedziny | M1: Data ostatnich odwiedzin | N1: Wolontariusze | O1: Sygnatura czasowa | P1: Kto odwiedza lub opiekuje się? | Q1: Stan zdrowotny | R1: Rodzaj oczekiwanej pomocy | S1: Odwiedzający | T1: Opis, potrzeby, przebieg odwiedzin | U1: Odwiedziny odbyły się (wpisać TAK) | V1: RODO | W1: Powód nie dołączenia
A2: 1 | B2: Podopieczny Nazwisko66 | C2: ADRES 25/55 | D2: 222333444 | E2: rodzina | I2: TAK | J2: zadzwonić pod koniec marca i dopytać o sytuację | L2: TAK | O2: 15:30 21.12.1212 | W2: zmarł
A3: 2 | B3: Podopieczny Nazwisko67 | C3: ADRES 25/56 | D3: 222333444 | E3: Marianna Załęga | I3: TAK | J3: do zastanowienia ale tylko "akcyjnie" mycie okien | K3: Prośba: akcja mycia okien | M3: 05.02.2025r. | N3: do wprowadzenia | O3: 15:30 21.12.1212
A4: 3 | B4: Podopieczny Nazwisko68 | C4: ADRES 25/57 | D4: 222333444 | E4: mops filia 7 | I4: TAK | J4: pan Pudełko zmarł końcem 2023 roku; zgloszenie nie aktualne | O4: 15:30 21.12.1212 | W4: rodzina przejęła opiekę
A5: 4 | B5: Podopieczny Nazwisko69 | C5: ADRES 25/58 | D5: 222333444 | E5: rodzina | I5: TAK | J5: do zastanowienia | O5: 15:30 21.12.1212 | W5: rodzina przejęła opiekę
A6: 5 | B6: Podopieczny Nazwisko70 | C6: ADRES 25/59 | D6: 222333444 | E6: rodzina | I6: TAK | J6: nie przyjęta do PaP - na ten moment zajmuje się rodzina | O6: 15:30 21.12.1212 | W6: rodzina przejęła opiekę
A7: 6 | B7: Podopieczny Nazwisko71 | C7: ADRES 25/60 | D7: 222333444 | E7: MOPS7 | I7: NIE | O7: 15:30 21.12.1212 | W7: rodzina przejęła opiekę
A8: 7 | B8: Podopieczny Nazwisko72 | C8: ADRES 25/61 | D8: 222333444 | E8: kolęda ks. Piotr | I8: do sprawdzenia | O8: 15:30 21.12.1212 | W8: rodzina przejęła opiekę
A9: 8 | B9: Podopieczny Nazwisko73 | C9: ADRES 25/62 | D9: 222333444 | E9: kolęda ks. Piotr | I9: do sprawdzenia | J9: do rozeznania | K9: 2-3 h tygodniowo | O9: 15:30 21.12.1212 | P9: corka | Q9: dobry | R9: 2-3 h wsparcia | W9: rodzina przejęła opiekę
A10: 9 | B10: Podopieczny Nazwisko74 | C10: ADRES 25/63 | D10: 222333444 | E10: kolęda ks. Piotr | I10: do sprawdzenia | J10: do sprawdzenia | O10: 15:30 21.12.1212 | W10: rodzina przejęła opiekę
A11: 10 | B11: Podopieczny Nazwisko75 | C11: ADRES 25/64 | D11: 222333444 | E11: kolęda ks. Piotr | I11: do sprawdzenia | J11: do rozeznania | O11: 15:30 21.12.1212 | W11: rodzina przejęła opiekę
A12: 11 | B12: Podopieczny Nazwisko76 | C12: ADRES 25/65 | D12: 222333444 | E12: kolęda ks. Piotr | I12: do sprawdzenia | J12: do rozeznania | O12: 15:30 21.12.1212 | W12: rodzina przejęła opiekę
A13: 12 | B13: Podopieczny Nazwisko77 | C13: ADRES 25/66 | D13: 222333444 | E13: kolęda ks. Piotr | I13: NIE | J13: do rozeznania | O13: 15:30 21.12.1212 | W13: rodzina przejęła opiekę
A14: 13 | B14: Podopieczny Nazwisko78 | C14: ADRES 25/67 | D14: 222333444 | E14: księża z NMP | I14: NIE | J14: pani zmarła 2024 | O14: 15:30 21.12.1212 | W14: rodzina przejęła opiekę
A15: 14 | B15: Podopieczny Nazwisko79 | C15: ADRES 25/68 | D15: 222333444 | E15: MOPS | I15: NIE | J15: poszukiwani wolontariusze | K15: odwiedziny, rozmowa | O15: 15:30 21.12.1212 | W15: rodzina przejęła opiekę
A16: 15 | B16: Podopieczny Nazwisko80 | C16: ADRES 25/69 | D16: 222333444 | E16: sąsiadka | I16: NIE | O16: 15:30 21.12.1212
A17: 16 | B17: Podopieczny Nazwisko81 | C17: ADRES 25/70 | D17: 222333444 | E17: Członek rodziny - córka | I17: NIE | J17: potrzebna pomoc, nie pilne, jeśli będą wprowadzić wolontrariuszy | K17: spacery | O17: 15:30 21.12.1212 | Q17: osoba niewidoma | R17: spacery
A18: 17 | B18: Podopieczny Nazwisko82 | C18: ADRES 25/71 | D18: 222333444 | E18: Członek rodziny - syn | I18: NIE | J18: do rozeznania | K18: zakupy 1 raz w tygodniu | O18: 15:30 21.12.1212 | P18: corka | Q18: dobry | R18: 2-3 h wsparcia
A19: 18 | B19: Podopieczny Nazwisko83 | C19: ADRES 25/72 | D19: 222333444 | E19: Członek rodziny - córka | I19: NIE | J19: pan zmarł 05.02.2025r. | O19: 15:30 21.12.1212
A20: 19 | B20: Podopieczny Nazwisko84 | C20: ADRES 25/73 | D20: 222333444 | E20: Maria Głowacka | I20: NIE | J20: wyjście na spacer | K20: Wyrażam zgodę na przetwarzanie danych osobowych podanych w formularzu w celu organizacji pomocy osobie starszej i samotnej przez Parafię NMP z Lourdes w Krakowie (KRS: 0000250448), która jest jednocześnie administratorem danych osobowych. Parafia NMP z Lourdes w Krakowie na moje życzenie usunie te dane. | L20: raczej tak! | M20: jest ktoś raz w tygodniu ktoś z rodziny, tylko spacery, czyta brailem, ponad 80 lat, syn w Wadowicach, wnuczek leczy się psychiczne, córka z Bukowna | O20: 15:30 21.12.1212 | P20: corka | Q20: dobry | R20: 2-3 h wsparcia | W20: zmarł
A21: 20 | B21: Podopieczny Nazwisko85 | C21: ADRES 25/74 | D21: 222333444 | E21: rodzina | I21: NIE | O21: 15:30 21.12.1212 | W21: zmarł
A22: 21 | B22: Podopieczny Nazwisko86 | C22: ADRES 25/75 | D22: 222333444 | E22: sąsiadka | I22: NIE | J22: do sprawdzenia | O22: 15:30 21.12.1212 | W22: zmarł
A23: 22 | B23: Podopieczny Nazwisko87 | C23: ADRES 25/76 | D23: 222333444 | E23: Członek rodziny | I23: NIE | J23: do sprawdzenia | O23: 15:30 21.12.1212 | W23: zmarł
A24: 23 | B24: Podopieczny Nazwisko88 | C24: ADRES 25/77 | D24: 222333444 | E24: Członek rodziny | I24: NIE | J24: do sprawdzenia | O24: 15:30 21.12.1212 | W24: zmarł
A25: 24 | B25: Podopieczny Nazwisko89 | C25: ADRES 25/78 | D25: 222333444 | E25: Członek rodziny | I25: NIE | J25: do sprawdzenia | O25: 15:30 21.12.1212 | W25: zmarł
A26: 25 | B26: Podopieczny Nazwisko90 | C26: ADRES 25/79 | D26: 222333444 | E26: sąsiadka | I26: NIE | J26: do sprawdzenia | O26: 15:30 21.12.1212 | W26: zmarł
A27: 26 | B27: Podopieczny Nazwisko91 | C27: ADRES 25/80 | D27: 222333444 | E27: Członek rodziny | I27: TAK | J27: do sprawdzenia | O27: 15:30 21.12.1212 | W27: zmarł
A28: 27 | B28: Podopieczny Nazwisko92 | C28: ADRES 25/81 | D28: 222333444 | E28: Członek rodziny | I28: TAK | J28: do sprawdzenia | O28: 15:30 21.12.1212 | Q28: osoba niewidoma | R28: spacery | W28: zmarł
A29: 28 | B29: Podopieczny Nazwisko93 | C29: ADRES 25/82 | D29: 222333444 | E29: synowa | I29: TAK | J29: do sprawdzenia | O29: 15:30 21.12.1212 | W29: zmarł
A30: 29 | B30: Podopieczny Nazwisko94 | C30: ADRES 25/83 | D30: 222333444 | E30: rodzina | I30: TAK | J30: do sprawdzenia | O30: 15:30 21.12.1212
A31: 30 | B31: Podopieczny Nazwisko95 | C31: ADRES 25/84 | D31: 222333444 | E31: rodzina | I31: TAK | J31: dopytać czy aktualne; znaleźć wolontariuszy | O31: 15:30 21.12.1212
A32: 31 | B32: Podopieczny Nazwisko96 | C32: ADRES 25/85 | D32: 222333444 | E32: mama | I32: TAK | J32: do sprawdzenia | O32: 15:30 21.12.1212
A33: 32 | B33: Podopieczny Nazwisko97 | C33: ADRES 25/86 | D33: 222333444 | E33: rodzina | I33: TAK | J33: do sprawdzenia | O33: 15:30 21.12.1212
A34: 33 | B34: Podopieczny Nazwisko98 | C34: ADRES 25/87 | D34: 222333444 | E34: rodzina | I34: TAK | J34: do sprawdzenia | O34: 15:30 21.12.1212
A35: 34 | B35: Podopieczny Nazwisko99 | C35: ADRES 25/88 | D35: 222333444 | E35: wolontariusz | F35: mariusz kopytko | G35: 123123123 | H35: brak mu towarzystwa | I35: TAK | J35: do sprawdzenia | L35: tak | M35: 45693 | O35: 15:30 21.12.1212 | P35: dzieci | Q35: ok | R35: zakupy | S35: jakis wolontariusz na pewno | T35: przychylny do wspolpracy | U35: TAK | V35: TAK

Sheet Podopieczni
A1: Nr | B1: Imię i nazwisko | C1: Adres | D1: Numer telefonu podopiecznego | E1: Numer telefonu rodziny/opiekuna | F1: Opis podopiecznego | G1: Status | H1: Grupa | I1: BO | J1: Data ostatnich odwiedzin księdza | K1: Termin ostatniego spotkania z wolontariuszami | L1: Historia
A2: 1 | B2: Podopieczny Nazwisko1 | C2: 742 Evergreen Terrace | D2: 111111111 | E2: Sąsiad Andrzej 555555555 | F2: Opis | G2: OBECNY | H2: A | I2: TAK | J2: 09.09.2022 | K2: 18.10.2079 | L2: Historia, opis podopiecznego
A3: 2 | B3: Podopieczny Nazwisko2 | C3: Springfield | D3: 111111112 | E3: Sąsiadka Karolina 666666666 | F3: Opis | G3: OBECNY | H3: A | I3: TAK | J3: 09.09.2022 | K3: 18.10.2080 | L3: Historia, opis podopiecznego
A4: 3 | B4: Podopieczny Nazwisko3 | C4: USA 221B Baker Street | D4: 111111113 | E4: Kolega Tomasz 777777777 | F4: Opis | G4: OBECNY | H4: A | I4: NIE | J4: 09.09.2022 | K4: 18.10.2081 | L4: Historia, opis podopiecznego
A5: 4 | B5: Podopieczny Nazwisko4 | C5: London | D5: 111111114 | E5: Koleżanka Anna 888888888 | F5: Opis | G5: OBECNY | H5: A | I5: NIE | J5: 09.09.2022 | K5: 18.10.2082 | L5: Historia, opis podopiecznego
A6: 5 | B6: Podopieczny Nazwisko5 | C6: UK 1600 Pennsylvania Ave NW | D6: 111111115 | E6: Współpracownik Paweł 999999999 | F6: Opis | G6: OBECNY | H6: A | I6: NIE | J6: 09.09.2022 | K6: 18.10.2083 | L6: Historia, opis podopiecznego
A7: 6 | B7: Podopieczny Nazwisko6 | C7: Washington | D7: 111111116 | E7: Kolega Piotr 101010101 | F7: Opis | G7: OBECNY | H7: A | I7: TAK | J7: 09.09.2022 | K7: 18.10.2084 | L7: Historia, opis podopiecznego
A8: 7 | B8: Podopieczny Nazwisko7 | C8: USA 10 Downing Street | D8: 111111117 | E8: Sąsiadka Elżbieta 202020202 | F8: Opis | G8: OBECNY | H8: B | I8: TAK | J8: 09.09.2022 | K8: 18.10.2085 | L8: Historia, opis podopiecznego
A9: 8 | B9: Podopieczny Nazwisko8 | C9: London | D9: 111111118 | E9: Koleżanka Magda 303030303 | F9: Opis | G9: OBECNY | H9: B | I9: NIE | J9: 09.09.2022 | K9: 18.10.2086 | L9: Historia, opis podopiecznego
A10: 9 | B10: Podopieczny Nazwisko9 | C10: UK 4 Privet Drive | D10: 111111119 | E10: Przyjaciel Michał 404040404 | F10: Opis | G10: OBECNY | H10: B | I10: TAK | J10: 09.09.2022 | K10: 18.10.2087 | L10: Historia, opis podopiecznego
A11: 10 | B11: Podopieczny Nazwisko10 | C11: Little Whinging | D11: 111111120 | E11: Rodzic Joanna 505050505 | F11: Opis | G11: OBECNY | H11: B | I11: TAK | J11: 09.09.2022 | K11: 18.10.2088 | L11: Historia, opis podopiecznego
A12: 11 | B12: Podopieczny Nazwisko11 | C12: UK 31 Spooner Street | D12: 111111121 | E12: Współpracownik Adam 606060606 | F12: Opis | G12: OBECNY | H12: B | I12: TAK | J12: 09.09.2022 | K12: 18.10.2089 | L12: Historia, opis podopiecznego
A13: 12 | B13: Podopieczny Nazwisko12 | C13: Quahog | D13: 111111122 | E13: Koleżanka Zofia 707070707 | F13: Opis | G13: OBECNY | H13: B | I13: TAK | J13: 09.09.2022 | K13: 18.10.2090 | L13: Historia, opis podopiecznego
... A40: 39 | B40: Podopieczny Nazwisko39 | C40: Australia Av. Paulista | D40: 111111147 | E40: Przyjaciel Paweł 353535353 | F40: Opis | G40: ZMARŁY | H40: E | I40: NIE | J40: 09.09.2022 | K40: 18.10.2117 | L40: Historia, opis podopiecznego
A41: 40 | B41: Podopieczny Nazwisko40 | C41: 1578 | D41: 111111148 | E41: Sąsiadka Danuta 363636363 | F41: Opis | G41: BYŁY | H41: E | I41: NIE | J41: 09.09.2022 | K41: 18.10.2118 | L41: Historia, opis podopiecznego
A42: 41 | B42: Podopieczny Nazwisko41 | C42: São Paulo | D42: 111111149 | E42: Kolega Łukasz 373737373 | F42: Opis | G42: ZMARŁY | H42: E | I42: NIE | J42: 09.09.2022 | K42: 18.10.2119 | L42: Historia, opis podopiecznego
A43: 42 | B43: Podopieczny Nazwisko42 | C43: Brazil Karl-Liebknecht-Str. 8 | D43: 111111150 | E43: Współpracownik Kamil 383838383 | F43: Opis | G43: DPS/ZOL | H43: E | I43: NIE | J43: 09.09.2022 | K43: 18.10.2120 | L43: Historia, opis podopiecznego
A44: 43 | B44: Podopieczny Nazwisko43 | C44: Berlin | D44: 111111151 | E44: Sąsiad Sławomir 393939393 | F44: Opis | G44: ZMARŁY | H44: E | I44: NIE | J44: 09.09.2022 | K44: 18.10.2121 | L44: Historia, opis podopiecznego
A45: 44 | B45: Podopieczny Nazwisko44 | C45: Germany Piazza San Marco | D45: 111111152 | E45: Koleżanka Natalia 404040404 | F45: Opis | G45: BYŁY | H45: E | I45: NIE | J45: 09.09.2022 | K45: 18.10.2122 | L45: Historia, opis podopiecznego
A46: 45 | B46: Podopieczny Nazwisko45 | C46: Venice | D46: 111111153 | E46: Przyjaciel Krzysztof 414141414 | F46: Opis | G46: BYŁY | H46: E | I46: NIE | J46: 09.09.2022 | K46: 18.10.2123 | L46: Historia, opis podopiecznego
A47: 46 | B47: Podopieczny Nazwisko46 | C47: Italy Plaza Mayor | D47: 111111154 | E47: Kolega Damian 424242424 | F47: Opis | G47: ZMARŁY | H47: E | I47: NIE | J47: 09.09.2022 | K47: 18.10.2124 | L47: Historia, opis podopiecznego
A48: 47 | B48: Podopieczny Nazwisko47 | C48: Madrid | D48: 111111155 | E48: Sąsiadka Iwona 434343434 | F48: Opis | G48: BYŁY | H48: E | I48: NIE | J48: 09.09.2022 | K48: 18.10.2125 | L48: Historia, opis podopiecznego
A49: 48 | B49: Podopieczny Nazwisko48 | C49: Spain 20 W 34th St | D49: 111111156 | E49: Koleżanka Joanna 444444444 | F49: Opis | G49: BYŁY | H49: E | I49: NIE | J49: 09.09.2022 | K49: 18.10.2126 | L49: Historia, opis podopiecznego
A50: 49 | B50: Podopieczny Nazwisko49 | C50: New York | D50: 111111157 | E50: Współpracownik Łukasz 454545454 | F50: Opis | G50: BYŁY | H50: E | I50: NIE | J50: 09.09.2022 | K50: 18.10.2127 | L50: Historia, opis podopiecznego
A51: 50 | B51: Podopieczny Nazwisko50 | C51: USA 350 Rue Saint-Paul | D51: 111111158 | E51: Sąsiad Grzegorz 464646464 | F51: Opis | G51: BYŁY | H51: E | I51: NIE | J51: 09.09.2022 | K51: 18.10.2128 | L51: Historia, opis podopiecznego
A52: 51 | B52: Podopieczny Nazwisko51 | C52: Montreal | D52: 111111159 | E52: Kolega Paweł 474747474 | F52: Opis | G52: ZMARŁY | H52: E | I52: NIE | J52: 09.09.2022 | K52: 18.10.2129 | L52: Historia, opis podopiecznego
A53: 52 | B53: Podopieczny Nazwisko52 | C53: Canada Piazza del Colosseo | D53: 111111160 | E53: Sąsiadka Teresa 484848484 | F53: Opis | G53: ZMARŁY | H53: E | I53: NIE | J53: 09.09.2022 | K53: 18.10.2130 | L53: Historia, opis podopiecznego
... A66: 65 | B66: Podopieczny Nazwisko65 | C66: Berlin | D66: 111111173 | E66: Współpracownik Jakub 616161616 | F66: Opis | G66: BYŁY | H66: E | I66: NIE | J66: 09.09.2022 | K66: 18.10.2143 | L66: Historia, opis podopiecznego

Sheet Rekrutacja Wolontariuszy
A1: Nr. | B1: Imię i nazwisko | C1: Adres e-mail | D1: Telefon | E1: Link do FB | F1: Data dołączenia | G1: Opis/Informacje | H1: Spotkanie Charyzmat | I1: Spotkanie Wspólnota | J1: Spotkanie Działanie | K1: Spotkanie Administracja | L1: Dlaczego chcesz do nas dołączyć? | M1: Które obszary szczególnie Cię interesują? | N1: Jak wygląda Twoja dyspozycyjność? (inne obowiązki, czas, pobyt w Krakowie) | O1: Czy nie jest dla Ciebie problemem cotygodniowe uczestnictwo w spotkaniach w środy o 19:30? | P1: Czy masz jakieś pytania bądź uwagi? | Q1: RODO
A2: 1 | B2: Imie i Nazwisko136 | C2: adres.email@email.com66 | D2: 111222333 | E2: link do FB | F2: 25.10.2023 | G2: student | H2: ok | I2: ok | L2: odpowiedź | M2: odpowiedź | N2: odpowiedź | O2: odpowiedź | P2: odpowiedź | Q2: odpowiedź
A3: 2 | B3: Imie i Nazwisko137 | C3: adres.email@email.com67 | D3: 111222333 | E3: link do FB | F3: 25.10.2024 | G3: student | J3: ok | L3: odpowiedź | M3: odpowiedź | N3: odpowiedź | O3: odpowiedź | P3: odpowiedź | Q3: odpowiedź
A4: 3 | B4: Imie i Nazwisko138 | C4: adres.email@email.com68 | D4: 111222333 | E4: link do FB | F4: 25.10.2025 | G4: student | L4: odpowiedź | M4: odpowiedź | N4: odpowiedź | O4: odpowiedź | P4: odpowiedź | Q4: odpowiedź
A5: 4 | B5: Imie i Nazwisko139 | C5: adres.email@email.com69 | D5: 111222333 | E5: link do FB | F5: 25.10.2026 | G5: student | I5: ok | K5: ok | L5: odpowiedź | M5: odpowiedź | N5: odpowiedź | O5: odpowiedź | P5: odpowiedź | Q5: odpowiedź
A6: 5 | B6: Imie i Nazwisko140 | C6: adres.email@email.com70 | D6: 111222333 | E6: link do FB | F6: 25.10.2027 | G6: student | H6: ok | L6: odpowiedź | M6: odpowiedź | N6: odpowiedź | O6: odpowiedź | P6: odpowiedź | Q6: odpowiedź
A7: 6 | B7: Imie i Nazwisko141 | C7: adres.email@email.com71 | D7: 111222333 | E7: link do FB | F7: 25.10.2028 | G7: student | L7: odpowiedź | M7: odpowiedź | N7: odpowiedź | O7: odpowiedź | P7: odpowiedź | Q7: odpowiedź
A8: 7 | B8: Imie i Nazwisko142 | C8: adres.email@email.com72 | D8: 111222333 | E8: link do FB | F8: 25.10.2029 | G8: student | L8: odpowiedź | M8: odpowiedź | N8: odpowiedź | O8: odpowiedź | P8: odpowiedź | Q8: odpowiedź
A9: 8 | B9: Imie i Nazwisko143 | C9: adres.email@email.com73 | D9: 111222333 | E9: link do FB | F9: 25.10.2030 | G9: student | J9: ok | K9: ok | L9: odpowiedź | M9: odpowiedź | N9: odpowiedź | O9: odpowiedź | P9: odpowiedź | Q9: odpowiedź
A10: 9 | B10: Imie i Nazwisko144 | C10: adres.email@email.com74 | D10: 111222333 | E10: link do FB | F10: 25.10.2031 | G10: student | H10: ok | J10: ok | L10: odpowiedź | M10: odpowiedź | N10: odpowiedź | O10: odpowiedź | P10: odpowiedź | Q10: odpowiedź
A11: 10 | B11: Imie i Nazwisko145 | C11: adres.email@email.com75 | D11: 111222333 | E11: link do FB | F11: 25.10.2032 | G11: student | I11: ok | K11: ok | L11: odpowiedź | M11: odpowiedź | N11: odpowiedź | O11: odpowiedź | P11: odpowiedź | Q11: odpowiedź
A12: 11 | B12: Imie i Nazwisko146 | C12: adres.email@email.com76 | D12: 111222333 | E12: link do FB | F12: 25.10.2033 | G12: student | J12: ok | K12: ok | L12: odpowiedź | M12: odpowiedź | N12: odpowiedź | O12: odpowiedź | P12: odpowiedź | Q12: odpowiedź
A13: 12 | B13: Imie i Nazwisko147 | C13: adres.email@email.com77 | D13: 111222333 | E13: link do FB | F13: 25.10.2034 | G13: student | I13: ok | L13: odpowiedź | M13: odpowiedź | N13: odpowiedź | O13: odpowiedź | P13: odpowiedź | Q13: odpowiedź
A14: 13 | B14: Imie i Nazwisko148 | C14: adres.email@email.com78 | D14: 111222333 | E14: link do FB | F14: 25.10.2035 | G14: student | H14: ok | L14: odpowiedź | M14: odpowiedź | N14: odpowiedź | O14: odpowiedź | P14: odpowiedź | Q14: odpowiedź
A15: 14 | B15: Imie i Nazwisko149 | C15: adres.email@email.com79 | D15: 111222333 | E15: link do FB | F15: 25.10.2036 | G15: studentka | H15: ok | L15: odpowiedź | M15: odpowiedź | N15: odpowiedź | O15: odpowiedź | P15: odpowiedź | Q15: odpowiedź
A16: 15 | B16: Imie i Nazwisko150 | C16: adres.email@email.com80 | D16: 111222333 | E16: link do FB | F16: 25.10.2037 | G16: studentka | K16: ok | L16: odpowiedź | M16: odpowiedź | N16: odpowiedź | O16: odpowiedź | P16: odpowiedź | Q16: odpowiedź
A17: 16 | B17: Imie i Nazwisko151 | C17: adres.email@email.com81 | D17: 111222333 | E17: link do FB | F17: 25.10.2038 | G17: studentka | J17: ok | L17: odpowiedź | M17: odpowiedź | N17: odpowiedź | O17: odpowiedź | P17: odpowiedź | Q17: odpowiedź
A18: 17 | B18: Imie i Nazwisko152 | C18: adres.email@email.com82 | D18: 111222333 | E18: link do FB | F18: 25.10.2039 | G18: studentka | H18: ok | I18: ok | L18: odpowiedź | M18: odpowiedź | N18: odpowiedź | O18: odpowiedź | P18: odpowiedź | Q18: odpowiedź
A19: 18 | B19: Imie i Nazwisko153 | C19: adres.email@email.com83 | D19: 111222333 | E19: link do FB | F19: 25.10.2040 | G19: studentka | I19: ok | J19: ok | K19: ok | L19: odpowiedź | M19: odpowiedź | N19: odpowiedź | O19: odpowiedź | P19: odpowiedź | Q19: odpowiedź
A20: 19 | B20: Imie i Nazwisko154 | C20: adres.email@email.com84 | D20: 111222333 | E20: link do FB | F20: 25.10.2041 | G20: studentka | H20: ok | L20: odpowiedź | M20: odpowiedź | N20: odpowiedź | O20: odpowiedź | P20: odpowiedź | Q20: odpowiedź
A21: 20 | B21: Imie i Nazwisko155 | C21: adres.email@email.com85 | D21: 111222333 | E21: link do FB | F21: 25.10.2042 | G21: studentka | K21: ok | L21: odpowiedź | M21: odpowiedź | N21: odpowiedź | O21: odpowiedź | P21: odpowiedź | Q21: odpowiedź
A22: 21 | B22: Imie i Nazwisko156 | C22: adres.email@email.com86 | D22: 111222333 | E22: link do FB | F22: 25.10.2043 | G22: studentka | K22: ok | L22: odpowiedź | M22: odpowiedź | N22: odpowiedź | O22: odpowiedź | P22: odpowiedź | Q22: odpowiedź
A23: 22 | B23: Imie i Nazwisko157 | C23: adres.email@email.com87 | D23: 111222333 | E23: link do FB | F23: 25.10.2044 | G23: studentka | I23: ok | J23: ok | L23: odpowiedź | M23: odpowiedź | N23: odpowiedź | O23: odpowiedź | P23: odpowiedź | Q23: odpowiedź
A24: 23 | B24: Imie i Nazwisko158 | C24: adres.email@email.com88 | D24: 111222333 | E24: link do FB | F24: 25.10.2045 | G24: studentka | K24: ok | L24: odpowiedź | M24: odpowiedź | N24: odpowiedź | O24: odpowiedź | P24: odpowiedź | Q24: odpowiedź
A25: 24 | B25: Imie i Nazwisko159 | C25: adres.email@email.com89 | D25: 111222333 | E25: link do FB | F25: 25.10.2046 | G25: studentka | J25: ok | L25: odpowiedź | M25: odpowiedź | N25: odpowiedź | O25: odpowiedź | P25: odpowiedź | Q25: odpowiedź
A26: 25 | B26: Imie i Nazwisko160 | C26: adres.email@email.com90 | D26: 111222333 | E26: link do FB | F26: 25.10.2047 | G26: studentka | H26: ok | I26: ok | J26: ok | K26: ok | L26: odpowiedź | M26: odpowiedź | N26: odpowiedź | O26: odpowiedź | P26: odpowiedź | Q26: odpowiedź

Sheet Wolontariusze
A1: Nr. | B1: Imię i Nazwisko | C1: Adres e-mail | D1: Telefon | E1: Link do FB | F1: Data dołączenia | G1: Opis/Informacje | H1: Przydzielony podopieczny | I1: Grupa podopiecznych | J1: Pomoc indywidualna | K1: Remonty | L1: Grupa porządkowa | M1: Fizjoterapia | N1: Księgowość | O1: Festyn Seniora | P1: Szkolenia | Q1: Media | R1: Klub seniora | S1: Muzyczni | T1: Gastronomia | U1: Zbieranie funduszy | V1: Aktualne role | W1: Historia | X1: Wymagana akcja | Y1: Bieżąca sytuacja | Z1: Status | AA1: Data odejścia | AB1: Dlaczego chcesz do nas dołączyć? | AC1: Które obszary szczególnie Cię interesują? | AD1: Jak wygląda Twoja dyspozycyjność? (inne obowiązki, czas, pobyt w Krakowie) | AE1: Czy nie jest dla Ciebie problemem cotygodniowe uczestnictwo w spotkaniach w środy o 19:30? | AF1: Czy masz jakieś pytania bądź uwagi? | AG1: RODO
A2: 1 | B2: Imie i Nazwisko1 | C2: adres.email@email.com1 | D2: 111222333 | E2: link do FB | F2: 01.10.2021 | G2: student | H2: Podopieczny Nazwisko37 | I2: =VLOOKUP(H2,Podopieczni!B:H,7,0) -> E | J2: TAK | L2: TAK | W2: historia, opis wolontariusza | Z2: Aktywny | AB2: odpowiedź | AC2: odpowiedź | AD2: odpowiedź | AE2: odpowiedź | AF2: odpowiedź | AG2: odpowiedź
A3: 2 | B3: Imie i Nazwisko2 | C3: adres.email@email.com2 | D3: 111222333 | E3: link do FB | F3: 01.10.2021 | G3: chętny do pomocy tylko w piątki | H3: Podopieczny Nazwisko10 | I3: =VLOOKUP(H3,Podopieczni!B:H,7,0) -> B | J3: TAK | L3: TAK | V3: Przewodnik | W3: historia, opis wolontariusza | Z3: Były | AA3: 10.05.23r. | AB3: odpowiedź | AC3: odpowiedź | AD3: odpowiedź | AE3: odpowiedź | AF3: odpowiedź | AG3: odpowiedź
A4: 3 | B4: Imie i Nazwisko3 | C4: adres.email@email.com3 | D4: 111222333 | E4: link do FB | F4: 29.03.2023 | H4: Podopieczny Nazwisko57 | I4: =VLOOKUP(H4,Podopieczni!B:H,7,0) -> E | J4: TAK | P4: TAK | W4: historia, opis wolontariusza | Z4: Były | AA4: 10.05.23r. | AB4: odpowiedź | AC4: odpowiedź | AD4: odpowiedź | AE4: odpowiedź | AF4: odpowiedź | AG4: odpowiedź
A5: 4 | B5: Imie i Nazwisko4 | C5: adres.email@email.com4 | D5: 111222333 | E5: link do FB | F5: 08.05.2024 | H5: Podopieczny Nazwisko19 | I5: =VLOOKUP(H5,Podopieczni!B:H,7,0) -> D | L5: TAK | W5: historia, opis wolontariusza | Z5: Były | AA5: 10.05.23r. | AB5: odpowiedź | AC5: odpowiedź | AD5: odpowiedź | AE5: odpowiedź | AF5: odpowiedź | AG5: odpowiedź
A6: 5 | B6: Imie i Nazwisko5 | C6: adres.email@email.com5 | D6: 111222333 | E6: link do FB | F6: 01.11.2024 | H6: Podopieczny Nazwisko22 | I6: =VLOOKUP(H6,Podopieczni!B:H,7,0) -> D | W6: historia, opis wolontariusza | Z6: Były | AA6: 10.05.23r. | AB6: odpowiedź | AC6: odpowiedź | AD6: odpowiedź | AE6: odpowiedź | AF6: odpowiedź | AG6: odpowiedź
A7: 6 | B7: Imie i Nazwisko6 | C7: adres.email@email.com6 | D7: 111222333 | E7: link do FB | F7: 01.10.2021 | H7: Podopieczny Nazwisko48 | I7: =VLOOKUP(H7,Podopieczni!B:H,7,0) -> E | J7: TAK | K7: TAK | L7: TAK | V7: Szef Kart BO | W7: historia, opis wolontariusza | Z7: Były | AA7: 10.05.23r. | AB7: odpowiedź | AC7: odpowiedź | AD7: odpowiedź | AE7: odpowiedź | AF7: odpowiedź | AG7: odpowiedź
A8: 7 | B8: Imie i Nazwisko7 | C8: adres.email@email.com7 | D8: 111222333 | E8: link do FB | F8: 25.10.2023 | G8: studentka | H8: Podopieczny Nazwisko50 | I8: =VLOOKUP(H8,Podopieczni!B:H,7,0) -> E | J8: TAK | L8: TAK | W8: historia, opis wolontariusza | Z8: Były | AA8: 10.05.23r. | AB8: odpowiedź | AC8: odpowiedź | AD8: odpowiedź | AE8: odpowiedź | AF8: odpowiedź | AG8: odpowiedź
A9: 8 | B9: Imie i Nazwisko8 | C9: adres.email@email.com8 | D9: 111222333 | E9: link do FB | F9: 01.01.2023 | H9: Podopieczny Nazwisko42 | I9: =VLOOKUP(H9,Podopieczni!B:H,7,0) -> E | J9: TAK | K9: TAK | W9: historia, opis wolontariusza | Z9: Były | AA9: 10.05.23r. | AB9: odpowiedź | AC9: odpowiedź | AD9: odpowiedź | AE9: odpowiedź | AF9: odpowiedź | AG9: odpowiedź
A10: 9 | B10: Imie i Nazwisko9 | C10: adres.email@email.com9 | D10: 111222333 | E10: link do FB | F10: 17.01.2024 | H10: Podopieczny Nazwisko59 | I10: =VLOOKUP(H10,Podopieczni!B:H,7,0) -> E | J10: TAK | O10: TAK | W10: historia, opis wolontariusza | Z10: Były | AA10: 10.05.23r. | AB10: odpowiedź | AC10: odpowiedź | AD10: odpowiedź | AE10: odpowiedź | AF10: odpowiedź | AG10: odpowiedź
A11: 10 | B11: Imie i Nazwisko10 | C11: adres.email@email.com10 | D11: 111222333 | E11: link do FB | F11: 17.01.2025 | G11: silny chłop | H11: Podopieczny Nazwisko12 | I11: =VLOOKUP(H11,Podopieczni!B:H,7,0) -> B | J11: TAK | L11: TAK | W11: historia, opis wolontariusza | Z11: Były | AA11: 10.05.23r. | AB11: odpowiedź | AC11: odpowiedź | AD11: odpowiedź | AE11: odpowiedź | AF11: odpowiedź | AG11: odpowiedź
A12: 11 | B12: Imie i Nazwisko11 | C12: adres.email@email.com11 | D12: 111222333 | E12: link do FB | F12: 11.10.2023 | H12: Podopieczny Nazwisko34 | I12: =VLOOKUP(H12,Podopieczni!B:H,7,0) -> E | J12: TAK | M12: TAK | R12: TAK | W12: historia, opis wolontariusza | Z12: Były | AA12: 10.05.23r. | AB12: odpowiedź | AC12: odpowiedź | AD12: odpowiedź | AE12: odpowiedź | AF12: odpowiedź | AG12: odpowiedź
A13: 12 | B13: Imie i Nazwisko12 | C13: adres.email@email.com12 | D13: 111222333 | E13: link do FB | F13: 01.11.2019 | H13: Podopieczny Nazwisko40 | I13: =VLOOKUP(H13,Podopieczni!B:H,7,0) -> E | J13: TAK | K13: TAK | L13: TAK | M13: TAK | V13: Szef Działu Porządków | W13: historia, opis wolontariusza | Z13: Były | AA13: 10.05.23r. | AB13: odpowiedź | AC13: odpowiedź | AD13: odpowiedź | AE13: odpowiedź | AF13: odpowiedź | AG13: odpowiedź
A14: 13 | B14: Imie i Nazwisko13 | C14: adres.email@email.com13 | D14: 111222333 | E14: link do FB | F14: 01.06.2023 | G14: student | H14: Podopieczny Nazwisko32 | I14: =VLOOKUP(H14,Podopieczni!B:H,7,0) -> E | J14: TAK | M14: TAK | W14: historia, opis wolontariusza | Z14: Były | AA14: 10.05.23r. | AB14: odpowiedź | AC14: odpowiedź | AD14: odpowiedź | AE14: odpowiedź | AF14: odpowiedź | AG14: odpowiedź
A15: 14 | B15: Imie i Nazwisko14 | C15: adres.email@email.com14 | D15: 111222333 | E15: link do FB | F15: 01.07.2022 | G15: student | H15: Podopieczny Nazwisko36 | I15: =VLOOKUP(H15,Podopieczni!B:H,7,0) -> E | J15: TAK | M15: TAK | W15: historia, opis wolontariusza | Z15: Były | AA15: 10.05.23r. | AB15: odpowiedź | AC15: odpowiedź | AD15: odpowiedź | AE15: odpowiedź | AF15: odpowiedź | AG15: odpowiedź
A16: 15 | B16: Imie i Nazwisko15 | C16: adres.email@email.com15 | D16: 111222333 | E16: link do FB | F16: 01.04.2021 | G16: student | H16: Podopieczny Nazwisko30 | I16: =VLOOKUP(H16,Podopieczni!B:H,7,0) -> E | J16: TAK | M16: TAK | W16: historia, opis wolontariusza | Z16: Były | AA16: 10.05.23r. | AB16: odpowiedź | AC16: odpowiedź | AD16: odpowiedź | AE16: odpowiedź | AF16: odpowiedź | AG16: odpowiedź
A17: 16 | B17: Imie i Nazwisko16 | C17: adres.email@email.com16 | D17: 111222333 | E17: link do FB | F17: 01.04.2021 | G17: student | H17: Podopieczny Nazwisko50 | I17: =VLOOKUP(H17,Podopieczni!B:H,7,0) -> E | J17: TAK | K17: TAK | L17: TAK | M17: TAK | V17: Przewodnik | W17: historia, opis wolontariusza | Z17: Były | AA17: 10.05.23r. | AB17: odpowiedź | AC17: odpowiedź | AD17: odpowiedź | AE17: odpowiedź | AF17: odpowiedź | AG17: odpowiedź
A18: 17 | B18: Imie i Nazwisko17 | C18: adres.email@email.com17 | D18: 111222333 | E18: link do FB | F18: 01.10.2021 | G18: student | H18: Podopieczny Nazwisko61 | I18: =VLOOKUP(H18,Podopieczni!B:H,7,0) -> E | J18: TAK | M18: TAK | W18: historia, opis wolontariusza | Z18: Były | AA18: 10.05.23r. | AB18: odpowiedź | AC18: odpowiedź | AD18: odpowiedź | AE18: odpowiedź | AF18: odpowiedź | AG18: odpowiedź
A19: 18 | B19: Imie i Nazwisko18 | C19: adres.email@email.com18 | D19: 111222333 | E19: link do FB | F19: 01.10.2021 | G19: student | H19: Podopieczny Nazwisko42 | I19: =VLOOKUP(H19,Podopieczni!B:H,7,0) -> E | J19: TAK | M19: TAK | N19: TAK | W19: historia, opis wolontariusza | Z19: Były | AA19: 10.05.23r. | AB19: odpowiedź | AC19: odpowiedź | AD19: odpowiedź | AE19: odpowiedź | AF19: odpowiedź | AG19: odpowiedź
A20: 19 | B20: Imie i Nazwisko19 | C20: adres.email@email.com19 | D20: 111222333 | E20: link do FB | F20: 01.03.2022 | G20: student | H20: Podopieczny Nazwisko37 | I20: =VLOOKUP(H20,Podopieczni!B:H,7,0) -> E | J20: TAK | M20: TAK | N20: TAK | W20: historia, opis wolontariusza | Z20: Były | AA20: 10.05.23r. | AB20: odpowiedź | AC20: odpowiedź | AD20: odpowiedź | AE20: odpowiedź | AF20: odpowiedź | AG20: odpowiedź
A21: 20 | B21: Imie i Nazwisko20 | C21: adres.email@email.com20 | D21: 111222333 | E21: link do FB | F21: 14.02.2024 | G21: student | H21: Podopieczny Nazwisko35 | I21: =VLOOKUP(H21,Podopieczni!B:H,7,0) -> E | J21: TAK | M21: TAK | N21: TAK | W21: historia, opis wolontariusza | Z21: Były | AA21: 10.05.23r. | AB21: odpowiedź | AC21: odpowiedź | AD21: odpowiedź | AE21: odpowiedź | AF21: odpowiedź | AG21: odpowiedź
A22: 21 | B22: Imie i Nazwisko21 | C22: adres.email@email.com21 | D22: 111222333 | E22: link do FB | F22: 27.09.2023 | G22: student | H22: Podopieczny Nazwisko5 | I22: =VLOOKUP(H22,Podopieczni!B:H,7,0) -> A | J22: TAK | N22: TAK | W22: historia, opis wolontariusza | Z22: Były | AA22: 10.05.23r. | AB22: odpowiedź | AC22: odpowiedź | AD22: odpowiedź | AE22: odpowiedź | AF22: odpowiedź | AG22: odpowiedź
A23: 22 | B23: Imie i Nazwisko22 | C23: adres.email@email.com22 | D23: 111222333 | E23: link do FB | F23: 27.09.2023 | G23: studentka | H23: Podopieczny Nazwisko38 | I23: =VLOOKUP(H23,Podopieczni!B:H,7,0) -> E | J23: TAK | N23: TAK | W23: historia, opis wolontariusza | Z23: Były | AA23: 10.05.23r. | AB23: odpowiedź | AC23: odpowiedź | AD23: odpowiedź | AE23: odpowiedź | AF23: odpowiedź | AG23: odpowiedź
A24: 23 | B24: Imie i Nazwisko23 | C24: adres.email@email.com23 | D24: 111222333 | E24: link do FB | F24: 18.10.2023 | G24: studentka | H24: Podopieczny Nazwisko47 | I24: =VLOOKUP(H24,Podopieczni!B:H,7,0) -> E | J24: TAK | K24: TAK | L24: TAK | N24: TAK | V24: Przewodnik | W24: historia, opis wolontariusza | Z24: Aktywny | AB24: odpowiedź | AC24: odpowiedź | AD24: odpowiedź | AE24: odpowiedź | AF24: odpowiedź | AG24: odpowiedź
A25: 24 | B25: Imie i Nazwisko24 | C25: adres.email@email.com24 | D25: 111222333 | E25: link do FB | F25: 27.09.2023 | G25: studentka | H25: Podopieczny Nazwisko20 | I25: =VLOOKUP(H25,Podopieczni!B:H,7,0) -> D | J25: TAK | N25: TAK | W25: historia, opis wolontariusza | Z25: Aktywny | AB25: odpowiedź | AC25: odpowiedź | AD25: odpowiedź | AE25: odpowiedź | AF25: odpowiedź | AG25: odpowiedź
A26: 25 | B26: Imie i Nazwisko25 | C26: adres.email@email.com25 | D26: 111222333 | E26: link do FB | F26: 18.10.2023 | G26: studentka | H26: Podopieczny Nazwisko45 | I26: =VLOOKUP(H26,Podopieczni!B:H,7,0) -> E | J26: TAK | N26: TAK | T26: TAK | W26: historia, opis wolontariusza | Z26: Aktywny | AB26: odpowiedź | AC26: odpowiedź | AD26: odpowiedź | AE26: odpowiedź | AF26: odpowiedź | AG26: odpowiedź
A27: 26 | B27: Imie i Nazwisko26 | C27: adres.email@email.com26 | D27: 111222333 | E27: link do FB | F27: 27.09.2023 | G27: studentka | H27: Podopieczny Nazwisko26 | I27: =VLOOKUP(H27,Podopieczni!B:H,7,0) -> E | J27: TAK | V27: Przewodnik | W27: historia, opis wolontariusza | Z27: Aktywny | AB27: odpowiedź | AC27: odpowiedź | AD27: odpowiedź | AE27: odpowiedź | AF27: odpowiedź | AG27: odpowiedź
A28: 27 | B28: Imie i Nazwisko27 | C28: adres.email@email.com27 | D28: 111222333 | E28: link do FB | F28: 18.10.2023 | G28: studentka | H28: Podopieczny Nazwisko54 | I28: =VLOOKUP(H28,Podopieczni!B:H,7,0) -> E | J28: TAK | W28: historia, opis wolontariusza | Z28: Aktywny | AB28: odpowiedź | AC28: odpowiedź | AD28: odpowiedź | AE28: odpowiedź | AF28: odpowiedź | AG28: odpowiedź
A29: 28 | B29: Imie i Nazwisko28 | C29: adres.email@email.com28 | D29: 111222333 | E29: link do FB | F29: 01.03.2023 | G29: studentka | H29: Podopieczny Nazwisko33 | I29: =VLOOKUP(H29,Podopieczni!B:H,7,0) -> E | J29: TAK | K29: TAK | W29: historia, opis wolontariusza | Z29: Aktywny | AB29: odpowiedź | AC29: odpowiedź | AD29: odpowiedź | AE29: odpowiedź | AF29: odpowiedź | AG29: odpowiedź
A30: 29 | B30: Imie i Nazwisko29 | C30: adres.email@email.com29 | D30: 111222333 | E30: link do FB | F30: 01.03.2023 | G30: studentka | H30: Podopieczny Nazwisko17 | I30: =VLOOKUP(H30,Podopieczni!B:H,7,0) -> D | J30: TAK | R30: TAK | V30: Szef DA | W30: historia, opis wolontariusza | Z30: Aktywny | AB30: odpowiedź | AC30: odpowiedź | AD30: odpowiedź | AE30: odpowiedź | AF30: odpowiedź | AG30: odpowiedź
A31: 30 | B31: Imie i Nazwisko30 | C31: adres.email@email.com30 | D31: 111222333 | E31: link do FB | F31: 01.03.2023 | G31: studentka | H31: Podopieczny Nazwisko33 | I31: =VLOOKUP(H31,Podopieczni!B:H,7,0) -> E | J31: TAK | W31: historia, opis wolontariusza | Z31: Aktywny | AB31: odpowiedź | AC31: odpowiedź | AD31: odpowiedź | AE31: odpowiedź | AF31: odpowiedź | AG31: odpowiedź
A32: 31 | B32: Imie i Nazwisko31 | C32: adres.email@email.com31 | D32: 111222333 | E32: link do FB | F32: 01.02.2020 | H32: Podopieczny Nazwisko15 | I32: =VLOOKUP(H32,Podopieczni!B:H,7,0) -> C | J32: TAK | K32: TAK | L32: TAK | W32: historia, opis wolontariusza | Z32: Aktywny | AB32: odpowiedź | AC32: odpowiedź | AD32: odpowiedź | AE32: odpowiedź | AF32: odpowiedź | AG32: odpowiedź
A33: 32 | B33: Imie i Nazwisko32 | C33: adres.email@email.com32 | D33: 111222333 | E33: link do FB | F33: 01.06.2020 | H33: Podopieczny Nazwisko32 | I33: =VLOOKUP(H33,Podopieczni!B:H,7,0) -> E | J33: TAK | W33: historia, opis wolontariusza | Z33: Aktywny | AB33: odpowiedź | AC33: odpowiedź | AD33: odpowiedź | AE33: odpowiedź | AF33: odpowiedź | AG33: odpowiedź
A34: 33 | B34: Imie i Nazwisko33 | C34: adres.email@email.com33 | D34: 111222333 | E34: link do FB | F34: 01.04.2022 | H34: Podopieczny Nazwisko49 | I34: =VLOOKUP(H34,Podopieczni!B:H,7,0) -> E | J34: TAK | W34: historia, opis wolontariusza | Z34: Aktywny | AB34: odpowiedź | AC34: odpowiedź | AD34: odpowiedź | AE34: odpowiedź | AF34: odpowiedź | AG34: odpowiedź
A35: 34 | B35: Imie i Nazwisko34 | C35: adres.email@email.com34 | D35: 111222333 | E35: link do FB | F35: 01.03.2023 | H35: Podopieczny Nazwisko51 | I35: =VLOOKUP(H35,Podopieczni!B:H,7,0) -> E | J35: TAK | W35: historia, opis wolontariusza | Z35: Aktywny | AB35: odpowiedź | AC35: odpowiedź | AD35: odpowiedź | AE35: odpowiedź | AF35: odpowiedź | AG35: odpowiedź
A36: 35 | B36: Imie i Nazwisko35 | C36: adres.email@email.com35 | D36: 111222333 | E36: link do FB | F36: 01.03.2023 | H36: Podopieczny Nazwisko44 | I36: =VLOOKUP(H36,Podopieczni!B:H,7,0) -> E | J36: TAK | K36: TAK | L36: TAK | W36: historia, opis wolontariusza | Z36: Aktywny | AB36: odpowiedź | AC36: odpowiedź | AD36: odpowiedź | AE36: odpowiedź | AF36: odpowiedź | AG36: odpowiedź
A37: 36 | B37: Imie i Nazwisko36 | C37: adres.email@email.com36 | D37: 111222333 | E37: link do FB | F37: 01.03.2023 | H37: Podopieczny Nazwisko29 | I37: =VLOOKUP(H37,Podopieczni!B:H,7,0) -> E | J37: TAK | K37: TAK | L37: TAK | W37: historia, opis wolontariusza | Z37: Aktywny | AB37: odpowiedź | AC37: odpowiedź | AD37: odpowiedź | AE37: odpowiedź | AF37: odpowiedź | AG37: odpowiedź
A38: 37 | B38: Imie i Nazwisko37 | C38: adres.email@email.com37 | D38: 111222333 | E38: link do FB | F38: 01.03.2023 | H38: Podopieczny Nazwisko11 | I38: =VLOOKUP(H38,Podopieczni!B:H,7,0) -> B | J38: TAK | K38: TAK | L38: TAK | W38: historia, opis wolontariusza | Z38: Aktywny | AB38: odpowiedź | AC38: odpowiedź | AD38: odpowiedź | AE38: odpowiedź | AF38: odpowiedź | AG38: odpowiedź
A39: 38 | B39: Imie i Nazwisko38 | C39: adres.email@email.com38 | D39: 111222333 | E39: link do FB | F39: 20.03.2024 | H39: Podopieczny Nazwisko64 | I39: =VLOOKUP(H39,Podopieczni!B:H,7,0) -> E | J39: TAK | W39: historia, opis wolontariusza | Z39: Aktywny | AB39: odpowiedź | AC39: odpowiedź | AD39: odpowiedź | AE39: odpowiedź | AF39: odpowiedź | AG39: odpowiedź
A40: 39 | B40: Imie i Nazwisko39 | C40: adres.email@email.com39 | D40: 111222333 | E40: link do FB | F40: 01.03.2023 | H40: Podopieczny Nazwisko56 | I40: =VLOOKUP(H40,Podopieczni!B:H,7,0) -> E | J40: TAK | K40: TAK | W40: historia, opis wolontariusza | Z40: Aktywny | AB40: odpowiedź | AC40: odpowiedź | AD40: odpowiedź | AE40: odpowiedź | AF40: odpowiedź | AG40: odpowiedź
...
